Workbook

Sheet 총  괄 
A1: 월 간 보 고 총 괄 ( 토목부 )
A2: 1. 공 정 실 적 보 고 | J2: (단위: 백만원)
A3: 구 부 | B3: 건수 (인원) | C3: 계약 금액 (V A T 제외) | D3: 수행 금액 | E3: (7월)공정 환산금액 | F3: (8월)공정 환산금액 | G3: 당해년도 공정합계 | H3: 공정 잔액 | I3: 공정-수금 차액 | J3: 비 고 | L3: 공정 | M3: 1월 | N3: 2월 | O3: 3월 | P3: 4월 | Q3: 5월 | R3: 6월 | S3: 7월 | T3: 8월 | U3: 9월 | V3: 10월 | W3: 11월 | X3: 12월 | Y3: 계
A4: 수행업무 | B4: =수행과업!A60 -> 15 | C4: =수행과업!E64 -> 7332.8773 | D4: =수행과업!G64 -> 4471.2555 | E4: =S4 -> 21.604644 | F4: =T4 -> 11.191149 | G4: =수행과업!AJ65 -> 72.021444 | H4: =수행과업!AK65 -> 2065.3784 | I4: =수행과업!AH64 -> 2497.4273 | L4: 수행업무 | M4: =수행과업!K64 -> 0.23355682 | N4: =수행과업!M64 -> 1.7422727 | O4: =수행과업!O64 -> 6.8481231 | P4: =수행과업!Q64 -> 7.1117594 | Q4: =수행과업!S64 -> 9.4271344 | R4: =수행과업!U64 -> 13.862805 | S4: =수행과업!W64 -> 21.604644 | T4: =수행과업!Y64 -> 11.191149 | U4: =수행과업!AA64 -> 0 | V4: =수행과업!AC64 -> 0 | W4: =수행과업!AE64 -> 0 | X4: =수행과업!AG64 -> 0 | Y4: =SUM(M4:X4) -> 72.021444
A5: 부서협조 | B5: =부서협조!A11 -> 3 | C5: =부서협조!E15 -> 284.04767 | D5: =부서협조!G15 -> 234.04767 | E5: =S5 -> 0.26095334 | F5: =T5 -> 0.26095334 | G5: =부서협조!AJ16 -> 2.8704867 | H5: =부서협조!AK16 -> 204.49381 | L5: 부서협조 | M5: =부서협조!K15 -> 0.39143001 | N5: =부서협조!M15 -> 0.39143001 | O5: =부서협조!O15 -> 0.39143001 | P5: =부서협조!Q15 -> 0.52190668 | Q5: =부서협조!S15 -> 0.39143001 | R5: =부서협조!U15 -> 0.26095334 | S5: =부서협조!W15 -> 0.26095334 | T5: =부서협조!Y15 -> 0.26095334 | U5: =부서협조!AA15 -> 0 | V5: =부서협조!AC15 -> 0 | W5: =부서협조!AE15 -> 0 | X5: =부서협조!AG15 -> 0 | Y5: =SUM(M5:X5) -> 2.8704867
A6: 일괄외주 | B6: ='일괄외주관리(없음)-출력X'!A15 -> 0 | C6: ='일괄외주관리(없음)-출력X'!E19 -> 0 | L6: 계 | M6: =SUM(M4:M5) -> 0.62498683 | N6: =SUM(N4:N5) -> 2.1337027 | O6: =SUM(O4:O5) -> 7.2395531 | P6: =SUM(P4:P5) -> 7.6336661 | Q6: =SUM(Q4:Q5) -> 9.8185644 | R6: =SUM(R4:R5) -> 14.123758 | S6: =SUM(S4:S5) -> 21.865597 | T6: =SUM(T4:T5) -> 11.452102 | ... X6: =SUM(X4:X5) -> 0 | Y6: =SUM(M6:X6) -> 74.891931
A7: 계 | B7: =SUM(B4:B6) -> 18 | C7: =SUM(C4:C6) -> 7616.9249 | D7: =SUM(D4:D6) -> 4705.3032 | E7: =SUM(E4:E6) -> 21.865597 | F7: =SUM(F4:F6) -> 11.452102 | G7: =SUM(G4:G6) -> 74.891931 | H7: =SUM(H4:H6) -> 2269.8722 | I7: =SUM(I4:I6) -> 2497.4273 | J7: 기술지원 등 ( 명 제외)
A8: 인당 | B8: 6 | C8: =D7/C7 -> 0.61774315 | E8: =E7/B8 -> 3.6442662 | F8: =F7/B8 -> 1.9086836 | G8: =G7/B8 -> 12.481988 | H8: =H7/B8 -> 378.31203
A10: 2. 보고 사항
A11: 인원 관련 : 6명 - 임원 2, 부장 1, 차장 2, 대리 1 (특이사항 없음)
A13: 주요보고사항 : 용인 역삼 임시총회 결과에 따른 조합 업무 협의
A15: 추진 사업 : 용봉산 출렁다리설치공사 기본 및 실시설계 용역 / 홍성군
A19: 3. 착수 및 중지 현황 (착수, 재착수, 중지 및 예정 사업) | J19: (단위: 백만원)
A20: 용역명 | D20: 발주처 | E20: 금액 | F20: 착수일 (재착수) | G20: 중지일 (예정일) | H20: 과업기간 (잔여일) | I20: 비 고
A21: 신성리갈대밭 관광지 지정 및 조성계획 수립용역 | D21: 서천군 | E21: =수행과업!E32 -> 108.10456 | F21: 8.22 | H21: 360일 | I21: 신규과업 착수 한종70+천마30+대웅(측량분담)
A25: 4. 전월 수금 결과보고 | J25: (단위: 백만원)
A26: 항목 | B26: 건수 | C26: 수금액 | D26: 미 수금 내용: 추가수금 건: | E26: 없음
A27: 계획 | B27: 4 | C27: 47
A28: 실적 | B28: 4 | C28: 47
A29: 차액 | C29: =C28-C27 -> 0 | D29: 추가 수금 건: | E29: 없음
A31: 5. 준공예정사업 | J31: (단위: 백만원)
A32: 용 역 명 | D32: 발주처 | E32: 계약금액 | F32: 준공예정일 | G32: 수금예정액 | H32: 비 고
A37: 소 계 | E37: =SUM(E33:E36) -> 0 | G37: =SUM(G33:G36) -> 0
A38: 6. 선금 및 기성예정사업 | J38: (단위: 백만원)
A39: 용 역 명 | D39: 발주처 | E39: 계약금액 | F39: 신청예정일 | G39: 수금예정액 | H39: 비 고
A42: 소 계 | G42: =SUM(G40:G41) -> 0
A44: 5.준공+6.선금기성 합 계 | G44: =G42+G37 -> 0

Sheet 수행과업
A1: 월 간 공 정 보 고 ( 토 목 부 )
A2: 1. 수행업무 | AI2: (단위: 백만원) | AP2: =AN48+AN52+AN56+AN60 -> 46945000
A3: 순서 | B3: 사 업 명 [발주처] | C3: 과업기간 | D3: 금 액 현 황 | F3: 수행금액 | H3: 전년 공정 | I3: 당해 공정 | J3: 1월 공정 | L3: 2월 공정 | N3: 3월 공정 | P3: 4월 공정 | R3: 5월 공정 | T3: 6월 공정 | V3: 7월 공정 | X3: 8월 공정 | Z3: 9월 기성 | AB3: 10월 기성 | AD3: 11월 기성 | AF3: 12월 기성 | AH3: 주요보고사항 (공정-수금 차액) | AI3: 발주처/ 담당자 | AL3: JOB NO | AP3: VAT 별도 분석
A4: 1 | B4: 용인 역삼구역 도시개발사업 실시설계(변경) 용역 | C4: 16.08.01 | D4: 계약 | E4: =AN4/1100000 -> 2348 | F4: 수행 | G4: =E4*0.75-(G5+G6) -> 1306.1876 | H4: 0.9 | I4: =H4+K4+M4+O4+Q4+S4+U4+W4+Y4+AA4+AC4+AE4+AG4 -> 0.9 | J4: 공정 | L4: 공정 | N4: 공정 | P4: 공정 | R4: 공정 | T4: 공정 | V4: 공정 | X4: 공정 | Z4: 공정 | AB4: 공정 | AD4: 공정 | AF4: 공정 | AH4: 기성성과품 제출 예정 | AI4: 역삼조합 조합장:정동춘 국장:김기두 / 토목:문일형 구조:양상훈 지반:박경순 | AJ4: 당해공정금액 | AK4: 공정잔액 | AL4: 15-05 | AM4: 계약 | AN4: 2582800000 | AO4: 부서협조 | AP4: =SUM(AQ4:BM4) -> 227152363 | AQ4: 지반협조 | AR4: 74500363 | AS4: 구조협조 | AT4: 152652000 | AU4: 기타 | AW4: 기타 | AY4: 기타
C5: 17.12.31 (완료시) | D5: 수금 | E5: =AN5/1100000 -> 436.36364 | F5: 협조 | G5: =AP4/1000000 -> 227.15236 | J5: 환산 | K5: =$G4*K4 -> 0 | L5: 환산 | M5: =$G4*M4 -> 0 | N5: 환산 | O5: =$G4*O4 -> 0 | P5: 환산 | Q5: =$G4*Q4 -> 0 | R5: 환산 | S5: =$G4*S4 -> 0 | T5: 환산 | U5: =$G4*U4 -> 0 | V5: 환산 | W5: =$G4*W4 -> 0 | X5: 환산 | Y5: =$G4*Y4 -> 0 | Z5: 환산 | AA5: =$G4*AA4 -> 0 | AB5: 환산 | AC5: =$G4*AC4 -> 0 | AD5: 환산 | AE5: =$G4*AE4 -> 0 | AF5: 환산 | AG5: =$G4*AG4 -> 0 | AJ5: =(I4-H4)*G4 -> 0 | AK5: =(1-I4)*G4 -> 130.61876 | AM5: 수금 | AN5: 480000000 | AO5: 외주처리 | AP5: =SUM(AQ5:BM5) -> 227660000 | AQ5: 측량 | AR5: 50000000 | AS5: 하천설계 | AT5: 60000000 | AU5: 상하수도 | AV5: 85000000 | AW5: 아르바이트 | AX5: 21000000 | AY5: 아르바이트 | AZ5: 11660000
C6: 중지: 18.10.04 | D6: 잔액 | E6: =E4-E5 -> 1911.6364 | F6: 외주 등 | G6: =(AP5+AP6)/1000000 -> 227.66 | J6: 진행 공정 | K6: - | L6: 진행 공정 | M6: - | N6: 진행 공정 | O6: - | P6: 진행 공정 | Q6: - | R6: 진행 공정 | S6: - | T6: 진행 공정 | U6: - | V6: 진행 공정 | W6: - | X6: 진행 공정 | Y6: 기성성과품 정리 | Z6: 진행 공정 | AB6: 진행 공정 | AC6: 0 0 검토 0 0 산출 | AD6: 진행 공정 | AE6: 0 0 검토 0 0 산출 | AF6: 진행 공정 | AG6: 0 0 검토 0 0 산출 | AM6: 잔액 | AN6: =AN4-AN5 -> 2102800000 | AO6: 기타비용
B7: 용인역삼도시개발사업조합 | C7: 잔여: | D7: 수금율 | E7: =E5/E4 -> 0.18584482 | F7: 수행율 | G7: =(E4-(G5+G6)/0.7)/E4 -> 0.72328282 | AH7: =(I4-E7)*E4 -> 1676.8364 | AN7: =AN5/AN4 -> 0.18584482 | AO7: 합 계 | AP7: =SUM(AP4:AP6) -> 454812363
A8: 2 | B8: 용인 역삼구역 기술지원관리 용역 | C8: 17.08. | D8: 계약 | E8: =AN8/1100000 -> 3386 | F8: 수행 | G8: =E8*0.75-(G9+G10) -> 2539.5 | H8: 0.33 | I8: =H8+K8+M8+O8+Q8+S8+U8+W8+Y8+AA8+AC8+AE8+AG8 -> 0.33 | J8: 공정 | L8: 공정 | N8: 공정 | P8: 공정 | R8: 공정 | T8: 공정 | V8: 공정 | X8: 공정 | Z8: 공정 | AB8: 공정 | AD8: 공정 | AF8: 공정 | AH8: 임시총회 개최결과에 따른 업무협의 | AI8: 역삼조합 조합장:정동춘 국장:김기두 / 문일형,김대영,주성완,박찬용,박민규,최진현 | AJ8: 당해공정금액 | AK8: 공정잔액 | AL8: 17-04 | AM8: 계약 | AN8: 3724600000 | AO8: 부서협조 | AP8: =SUM(AQ8:BM8) -> 0 | AQ8: 지반협조 | AS8: 구조협조 | AU8: 기타 | AW8: 기타 | AY8: 기타
C9: 20.11. | D9: 수금 | E9: =AN9/1100000 -> 480 | F9: 협조 | G9: =AP8/1000000 -> 0 | J9: 환산 | K9: =$G8*K8 -> 0 | L9: 환산 | M9: =$G8*M8 -> 0 | N9: 환산 | O9: =$G8*O8 -> 0 | P9: 환산 | Q9: =$G8*Q8 -> 0 | R9: 환산 | S9: =$G8*S8 -> 0 | T9: 환산 | U9: =$G8*U8 -> 0 | V9: 환산 | W9: =$G8*W8 -> 0 | X9: 환산 | Y9: =$G8*Y8 -> 0 | Z9: 환산 | AA9: =$G8*AA8 -> 0 | AB9: 환산 | AC9: =$G8*AC8 -> 0 | AD9: 환산 | AE9: =$G8*AE8 -> 0 | AF9: 환산 | AG9: =$G8*AG8 -> 0 | AJ9: =(I8-H8)*G8 -> 0 | AK9: =(1-I8)*G8 -> 1701.465 | AM9: 수금 | AN9: 528000000 | AO9: 외주처리 | AP9: =SUM(AQ9:BM9) -> 0 | AQ9: 교통 | AS9: 경관 | AU9: 내역 | AW9: 용지 | AY9: 기타
C10: 중지: 18.10.04 | D10: 잔액 | E10: =E8-E9 -> 2906 | F10: 외주 등 | G10: =(AP9+AP10)/1000000 -> 0 | J10: 진행 공정 | L10: 진행 공정 | N10: 진행 공정 | P10: 진행 공정 | R10: 진행 공정 | T10: 진행 공정 | U10: 임시총회 자료 작성 | V10: 진행 공정 | W10: 홍보물 작성 | X10: 진행 공정 | Y10: 임시총회 개최(08/20) | Z10: 진행 공정 | AB10: 진행 공정 | AD10: 진행 공정 | AF10: 진행 공정 | AM10: 잔액 | AN10: =AN8-AN9 -> 3196600000 | AO10: 기타비용
B11: 용인역삼도시개발사업조합 | C11: 잔여: | D11: 수금율 | E11: =E9/E8 -> 0.14176019 | F11: 수행율 | G11: =(E8-(G9+G10)/0.7)/E8 -> 1 | AH11: =(I8-E11)*E8 -> 637.38 | AN11: =AN9/AN8 -> 0.14176019 | AO11: 합 계 | AP11: =SUM(AP8:AP10) -> 0
A12: 3 | B12: 용인 역삼구역 하수처리장 건설공사 기본 및 실시설계 용역 | C12: 16.08.01 | D12: 계약 | E12: =AN12/1100000 -> 416.09091 | F12: 수행 | G12: =E12*0.75-(G13+G14) -> 112.06818 | H12: 0.3 | I12: =H12+K12+M12+O12+Q12+S12+U12+W12+Y12+AA12+AC12+AE12+AG12 -> 0.3 | J12: 공정 | L12: 공정 | N12: 공정 | P12: 공정 | R12: 공정 | T12: 공정 | V12: 공정 | X12: 공정 | Z12: 공정 | AB12: 공정 | AD12: 공정 | AF12: 공정 | AH12: 업무대기 | AI12: 역삼조합 조합장:정동춘 국장:김기두 / 문일형,김대영,박민규 | AJ12: 당해공정금액 | AK12: 공정잔액 | AL12: 16-07 | AM12: 계약 | AN12: 457700000 | AO12: 부서협조 | AP12: =SUM(AQ12:BM12) -> 0 | AQ12: 지반협조 | AS12: 구조협조 | AU12: 기타 | AW12: 기타 | AY12: 기타
C13: 16.12.31 (완료시) | D13: 수금 | E13: =AN13/1100000 -> 156.73455 | F13: 협조 | G13: =AP12/1000000 -> 0 | J13: 환산 | K13: =$G12*K12 -> 0 | L13: 환산 | M13: =$G12*M12 -> 0 | N13: 환산 | O13: =$G12*O12 -> 0 | P13: 환산 | Q13: =$G12*Q12 -> 0 | R13: 환산 | S13: =$G12*S12 -> 0 | T13: 환산 | U13: =$G12*U12 -> 0 | V13: 환산 | W13: =$G12*W12 -> 0 | X13: 환산 | Y13: =$G12*Y12 -> 0 | Z13: 환산 | AA13: =$G12*AA12 -> 0 | AB13: 환산 | AC13: =$G12*AC12 -> 0 | AD13: 환산 | AE13: =$G12*AE12 -> 0 | AF13: 환산 | AG13: =$G12*AG12 -> 0 | AJ13: =(I12-H12)*G12 -> 0 | AK13: =(1-I12)*G12 -> 78.447727 | AM13: 수금 | AN13: 172408000 | AO13: 외주처리 | AP13: =SUM(AQ13:BM13) -> 200000000 | AQ13: 전기, 통신 | AR13: 100000000 | AS13: 조경 | AT13: 100000000 | AU13: 내역 | AW13: 용지 | AY13: 기타
C14: 중지: 18.10.01 | D14: 잔액 | E14: =E12-E13 -> 259.35636 | F14: 외주 등 | G14: =(AP13+AP14)/1000000 -> 200 | J14: 진행 공정 | L14: 진행 공정 | N14: 진행 공정 | P14: 진행 공정 | R14: 진행 공정 | T14: 진행 공정 | V14: 진행 공정 | W14: - | X14: 진행 공정 | Y14: - | Z14: 진행 공정 | AB14: 진행 공정 | AD14: 진행 공정 | AF14: 진행 공정 | AM14: 잔액 | AN14: =AN12-AN13 -> 285292000 | AO14: 기타비용
B15: 용인역삼도시개발사업조합 | C15: 잔여: | D15: 수금율 | E15: =E13/E12 -> 0.37668342 | F15: 수행율 | G15: =(E12-(G13+G14)/0.7)/E12 -> 0.31333687 | AH15: =(I12-E15)*E12 -> -31.907273 | AN15: =AN13/AN12 -> 0.37668342 | AO15: 합 계 | AP15: =SUM(AP12:AP14) -> 200000000
A16: 4 | B16: 용인 역삼구역 금학천 하천기본계획검토용역 | C16: 16.11.01 | D16: 계약 | E16: =AN16/1100000 -> 177.81818 | F16: 수행 | G16: =E16*0.75-(G17+G18) -> 73.363636 | H16: 0.6 | I16: =H16+K16+M16+O16+Q16+S16+U16+W16+Y16+AA16+AC16+AE16+AG16 -> 0.6 | J16: 공정 | L16: 공정 | N16: 공정 | P16: 공정 | R16: 공정 | T16: 공정 | V16: 공정 | X16: 공정 | Z16: 공정 | AB16: 공정 | AD16: 공정 | AF16: 공정 | AH16: 업무대기 | AI16: 역삼조합 조합장:정동춘 국장:김기두 / 문일형,김대영,박민규 | AJ16: 당해공정금액 | AK16: 공정잔액 | AL16: 16-12 | AM16: 계약 | AN16: 195600000 | AO16: 부서협조 | AP16: =SUM(AQ16:BM16) -> 0 | AQ16: 지반협조 | AS16: 구조협조 | AU16: 기타 | AW16: 기타 | AY16: 기타
C17: 17.07.31 (완료시) | D17: 수금 | E17: =AN17/1100000 -> 17.727273 | F17: 협조 | G17: =AP16/1000000 -> 0 | J17: 환산 | K17: =$G16*K16 -> 0 | L17: 환산 | M17: =$G16*M16 -> 0 | N17: 환산 | O17: =$G16*O16 -> 0 | P17: 환산 | Q17: =$G16*Q16 -> 0 | R17: 환산 | S17: =$G16*S16 -> 0 | T17: 환산 | U17: =$G16*U16 -> 0 | V17: 환산 | W17: =$G16*W16 -> 0 | X17: 환산 | Y17: =$G16*Y16 -> 0 | Z17: 환산 | AA17: =$G16*AA16 -> 0 | AB17: 환산 | AC17: =$G16*AC16 -> 0 | AD17: 환산 | AE17: =$G16*AE16 -> 0 | AF17: 환산 | AG17: =$G16*AG16 -> 0 | AJ17: =(I16-H16)*G16 -> 0 | AK17: =(1-I16)*G16 -> 29.345455 | AM17: 수금 | AN17: 19500000 | AO17: 외주처리 | AP17: =SUM(AQ17:BM17) -> 60000000 | AQ17: 수자원 | AR17: 60000000 | AS17: 경관 | AU17: 내역 | AW17: 용지 | AY17: 기타
C18: 중지: 18.10.04 | D18: 잔액 | E18: =E16-E17 -> 160.09091 | F18: 외주 등 | G18: =(AP17+AP18)/1000000 -> 60 | J18: 진행 공정 | L18: 진행 공정 | N18: 진행 공정 | P18: 진행 공정 | R18: 진행 공정 | T18: 진행 공정 | V18: 진행 공정 | W18: - | X18: 진행 공정 | Y18: - | Z18: 진행 공정 | AB18: 진행 공정 | AD18: 진행 공정 | AF18: 진행 공정 | AM18: 잔액 | AN18: =AN16-AN17 -> 176100000 | AO18: 기타비용
B19: 용인역삼도시개발사업조합 | C19: 잔여: | D19: 수금율 | E19: =E17/E16 -> 0.099693252 | F19: 수행율 | G19: =(E16-(G17+G18)/0.7)/E16 -> 0.5179667 | AH19: =(I16-E19)*E16 -> 88.963636 | AN19: =AN17/AN16 -> 0.099693252 | AO19: 합 계 | AP19: =SUM(AP16:AP18) -> 60000000
A20: 5 | B20: 예산 개발촉진지구 기반시설 기본 및 실시설계 용역 | C20: 14.06.30 | D20: 계약 | E20: =AN20/1100000 -> 363.73032 | F20: 수행 | G20: =E20*0.75-(G21+G22) -> 218.88724 | H20: 0.9 | I20: =H20+K20+M20+O20+Q20+S20+U20+W20+Y20+AA20+AC20+AE20+AG20 -> 0.9 | J20: 공정 | L20: 공정 | N20: 공정 | P20: 공정 | R20: 공정 | T20: 공정 | V20: 공정 | X20: 공정 | Z20: 공정 | AB20: 공정 | AD20: 공정 | AF20: 공정 | AH20: 실시계획인가 (변경) 서류작성 | AI20: 도시재생과 팀장:장정훈 감독:김영환 / 토목:박찬용 구조:양상훈 지반:유승주 | AJ20: 당해공정금액 | AK20: 공정잔액 | AL20: 14-08 | AM20: 계약 | AN20: 400103357 | AO20: 부서협조 | AP20: =SUM(AQ20:BM20) -> 42910500 | AQ20: 지반협조 | AR20: 9000000 | AS20: 구조협조 | AT20: 33910500 | AU20: 기타 | AW20: 기타 | AY20: 기타
C21: 17.09.30 | D21: 수금 | E21: =AN21/1100000 -> 255.39818 | F21: 협조 | G21: =AP20/1000000 -> 42.9105 | J21: 환산 | K21: =$G20*K20 -> 0 | L21: 환산 | M21: =$G20*M20 -> 0 | N21: 환산 | O21: =$G20*O20 -> 0 | P21: 환산 | Q21: =$G20*Q20 -> 0 | R21: 환산 | S21: =$G20*S20 -> 0 | T21: 환산 | U21: =$G20*U20 -> 0 | V21: 환산 | W21: =$G20*W20 -> 0 | X21: 환산 | Y21: =$G20*Y20 -> 0 | Z21: 환산 | AA21: =$G20*AA20 -> 0 | AB21: 환산 | AC21: =$G20*AC20 -> 0 | AD21: 환산 | AE21: =$G20*AE20 -> 0 | AF21: 환산 | AG21: =$G20*AG20 -> 0 | AJ21: =(I20-H20)*G20 -> 0 | AK21: =(1-I20)*G20 -> 21.888724 | AM21: 수금 | AN21: 280938000 | AO21: 외주처리 | AP21: =SUM(AQ21:BM21) -> 11000000 | AQ21: 부잔교 안전진담 및 자재검수 | AR21: 11000000 | AS21: 하천설계 | AU21: 상하수도 | AW21: 아르바이트 | AY21: 아르바이트
C22: 중지: 17.08.29 | D22: 잔액 | E22: =E20-E21 -> 108.33214 | F22: 외주 등 | G22: =(AP21+AP22)/1000000 -> 11 | J22: 진행 공정 | K22: 0 0 검토 0 0 산출 | L22: 진행 공정 | M22: 0 0 검토 0 0 산출 | N22: 진행 공정 | O22: 0 0 검토 0 0 산출 | P22: 진행 공정 | Q22: 0 0 검토 0 0 산출 | R22: 진행 공정 | S22: 0 0 검토 0 0 산출 | T22: 진행 공정 | V22: 진행 공정 | W22: - | X22: 진행 공정 | Y22: 실시계획인가(변경)서류작성 | Z22: 진행 공정 | AA22: 0 0 검토 0 0 산출 | AB22: 진행 공정 | AC22: 0 0 검토 0 0 산출 | AD22: 진행 공정 | AE22: 0 0 검토 0 0 산출 | AF22: 진행 공정 | AG22: 0 0 검토 0 0 산출 | AM22: 잔액 | AN22: =AN20-AN21 -> 119165357 | AO22: 기타비용
B23: 예산군 | C23: 잔여:33일 | D23: 수금율 | E23: =E21/E20 -> 0.70216357 | F23: 수행율 | G23: =(E20-(G21+G22)/0.7)/E20 -> 0.78826346 | AH23: =(I20-E23)*E20 -> 71.95911 | AN23: =AN21/AN20 -> 0.70216357 | AO23: 합 계 | AP23: =SUM(AP20:AP22) -> 53910500
A24: 6 | B24: 예당호 착한농촌체험세상 기본 및 실시설계 용역 | C24: 18.12.21 | D24: 계약 | E24: =AN24/1100000 -> 182.94237 | F24: 수행 | G24: =E24*0.75-(G25+G26) -> 88.30678 | I24: =H24+K24+M24+O24+Q24+S24+U24+W24+Y24+AA24+AC24+AE24+AG24 -> 0.4 | J24: 공정 | L24: 공정 | N24: 공정 | O24: 0.05 | P24: 공정 | Q24: 0.05 | R24: 공정 | S24: 0.05 | T24: 공정 | U24: 0.05 | V24: 공정 | W24: 0.1 | X24: 공정 | Y24: 0.1 | Z24: 공정 | AB24: 공정 | AD24: 공정 | AF24: 공정 | AH24: 기본계획도면, 1차설계적정성 검토 자료 작성 | AI24: 문화관광과 팀장:이관우 감독:박창현 / 토목:주성완 수자:박가영 교통:김영준 | AJ24: 당해공정금액 | AK24: 공정잔액 | AL24: 18-04 | AM24: 계약 | AN24: 201236610 | AO24: 부서협조 | AP24: =SUM(AQ24:BM24) -> 39900000 | AQ24: 교통협조 | AR24: 13300000 | AS24: 수자원협조 | AT24: 26600000 | AU24: 기타 | AW24: 기타 | AY24: 기타
C25: 20.03.14 | D25: 수금 | E25: =AN25/1100000 -> 74.850909 | F25: 협조 | G25: =AP24/1000000 -> 39.9 | J25: 환산 | K25: =$G24*K24 -> 0 | L25: 환산 | M25: =$G24*M24 -> 0 | N25: 환산 | O25: =$G24*O24 -> 4.415339 | P25: 환산 | Q25: =$G24*Q24 -> 4.415339 | R25: 환산 | S25: =$G24*S24 -> 4.415339 | T25: 환산 | U25: =$G24*U24 -> 4.415339 | V25: 환산 | W25: =$G24*W24 -> 8.830678 | X25: 환산 | Y25: =$G24*Y24 -> 8.830678 | Z25: 환산 | AA25: =$G24*AA24 -> 0 | AB25: 환산 | AC25: =$G24*AC24 -> 0 | AD25: 환산 | AE25: =$G24*AE24 -> 0 | AF25: 환산 | AG25: =$G24*AG24 -> 0 | AJ25: =(I24-H24)*G24 -> 35.322712 | AK25: =(1-I24)*G24 -> 52.984068 | AM25: 수금 | AN25: 82336000 | AO25: 외주처리 | AP25: =SUM(AQ25:BM25) -> 9000000 | AQ25: 산림조사 | AR25: 3000000 | AS25: 국외사례조사 | AT25: 6000000 | AU25: 내역 | AW25: 용지 | AY25: 기타
C26: 중지: | D26: 잔액 | E26: =E24-E25 -> 108.09146 | F26: 외주 등 | G26: =(AP25+AP26)/1000000 -> 9 | J26: 진행 공정 | L26: 진행 공정 | N26: 진행 공정 | P26: 진행 공정 | R26: 진행 공정 | T26: 진행 공정 | U26: 기본계획(안)작성 | V26: 진행 공정 | W26: 기본계획(안)작성 | X26: 진행 공정 | Y26: 기본계획 도면작성 | Z26: 진행 공정 | AB26: 진행 공정 | AD26: 진행 공정 | AF26: 진행 공정 | AM26: 잔액 | AN26: =AN24-AN25 -> 118900610 | AO26: 기타비용
B27: 예산군 | C27: 잔여: | D27: 수금율 | E27: =E25/E24 -> 0.4091502 | F27: 수행율 | G27: =(E24-(G25+G26)/0.7)/E24 -> 0.61814673 | AH27: =(I24-E27)*E24 -> -1.67396 | AN27: =AN25/AN24 -> 0.4091502 | AO27: 합 계 | AP27: =SUM(AP24:AP26) -> 48900000
A28: 7 | B28: 태조산공원 산림레포츠시설 조성사업 실시설계 및 공원조성계획(변경)용역 | C28: 19.02.28 | D28: 계약 | E28: =AN28/1100000 -> 116.20545 | F28: 수행 | G28: =E28*0.75-(G29+G30) -> 16.364091 | I28: =H28+K28+M28+O28+Q28+S28+U28+W28+Y28+AA28+AC28+AE28+AG28 -> 0.5 | J28: 공정 | L28: 공정 | M28: 0.05 | N28: 공정 | O28: 0.05 | P28: 공정 | Q28: 0.05 | R28: 공정 | S28: 0.05 | T28: 공정 | U28: 0.1 | V28: 공정 | W28: 0.1 | X28: 공정 | Y28: 0.1 | Z28: 공정 | AB28: 공정 | AD28: 공정 | AF28: 공정 | AH28: 도시공원심의 상정(9월 예정) | AI28: 산림휴양과 팀장:김주식 감독:김혜빈 / 토목:김대영 수자:박가영 지반:유승주 | AJ28: 당해공정금액 | AK28: 공정잔액 | AL28: 19-03 | AM28: 계약 | AN28: 127826000 | AO28: 부서협조 | AP28: =SUM(AQ28:BM28) -> 29790000 | AQ28: 지반협조 | AR28: 8630000 | AS28: 수자원협조 | AT28: 21160000 | AU28: 기타 | AW28: 기타 | AY28: 기타
C29: 19.10.25 | D29: 수금 | E29: =AN29/1100000 -> 34.854545 | F29: 협조 | G29: =AP28/1000000 -> 29.79 | J29: 환산 | K29: =$G28*K28 -> 0 | L29: 환산 | M29: =$G28*M28 -> 0.81820455 | N29: 환산 | O29: =$G28*O28 -> 0.81820455 | P29: 환산 | Q29: =$G28*Q28 -> 0.81820455 | R29: 환산 | S29: =$G28*S28 -> 0.81820455 | T29: 환산 | U29: =$G28*U28 -> 1.6364091 | V29: 환산 | W29: =$G28*W28 -> 1.6364091 | X29: 환산 | Y29: =$G28*Y28 -> 1.6364091 | Z29: 환산 | AA29: =$G28*AA28 -> 0 | AB29: 환산 | AC29: =$G28*AC28 -> 0 | AD29: 환산 | AE29: =$G28*AE28 -> 0 | AF29: 환산 | AG29: =$G28*AG28 -> 0 | AJ29: =(I28-H28)*G28 -> 8.1820455 | AK29: =(1-I28)*G28 -> 8.1820455 | AM29: 수금 | AN29: 38340000 | AO29: 외주처리 | AP29: =SUM(AQ29:BM29) -> 41000000 | AQ29: 측량 | AR29: 9000000 | AS29: 조경 | AT29: 29000000 | AU29: 조감도 | AV29: 3000000 | AW29: 용지 | AY29: 기타
C30: 중지: | D30: 잔액 | E30: =E28-E29 -> 81.350909 | F30: 외주 등 | G30: =(AP29+AP30)/1000000 -> 41 | J30: 진행 공정 | L30: 진행 공정 | N30: 진행 공정 | P30: 진행 공정 | R30: 진행 공정 | T30: 진행 공정 | U30: 기본계획안 작성 | V30: 진행 공정 | W30: 기본계획안 작성 | X30: 진행 공정 | Y30: 도시공원심의 자료작성 | Z30: 진행 공정 | AB30: 진행 공정 | AD30: 진행 공정 | AF30: 진행 공정 | AM30: 잔액 | AN30: =AN28-AN29 -> 89486000 | AO30: 기타비용
B31: 천안시 | C31: 잔여: | D31: 수금율 | E31: =E29/E28 -> 0.29993898 | F31: 수행율 | G31: =(E28-(G29+G30)/0.7)/E28 -> 0.12974333 | AH31: =(I28-E31)*E28 -> 23.248182 | AN31: =AN29/AN28 -> 0.29993898 | AO31: 합 계 | AP31: =SUM(AP28:AP30) -> 70790000
A32: 8 | B32: 신성리갈대밭 관광지 지정 및 조성계획 수립용역 | C32: 19.08.22 | D32: 계약 | E32: =AN32/1100000 -> 108.10456 | F32: 수행 | G32: =E32*0.75-(G33+G34) -> 37.383423 | I32: =H32+K32+M32+O32+Q32+S32+U32+W32+Y32+AA32+AC32+AE32+AG32 -> 0.01 | J32: 공정 | L32: 공정 | N32: 공정 | P32: 공정 | R32: 공정 | T32: 공정 | V32: 공정 | X32: 공정 | Y32: 0.01 | Z32: 공정 | AB32: 공정 | AD32: 공정 | AF32: 공정 | AH32: -착수계제출(8/22) -기본계획 검토 | AI32: 관광축제과 팀장:최순우 감독:김선화 / 토목:김대영 | AJ32: 당해공정금액 | AK32: 공정잔액 | AL32: 19-03 | AM32: 계약 | AN32: 118915020 | AO32: 부서협조 | AP32: =SUM(AQ32:BM32) -> 43695000 | AQ32: 교통협조 | AS32: 수자원협조 | AT32: 43695000 | AU32: 기타 | AW32: 기타 | AY32: 기타
C33: 20.08.15 | D33: 수금 | E33: =AN33/1100000 -> 0 | F33: 협조 | G33: =AP32/1000000 -> 43.695 | J33: 환산 | K33: =$G32*K32 -> 0 | L33: 환산 | M33: =$G32*M32 -> 0 | N33: 환산 | O33: =$G32*O32 -> 0 | P33: 환산 | Q33: =$G32*Q32 -> 0 | R33: 환산 | S33: =$G32*S32 -> 0 | T33: 환산 | U33: =$G32*U32 -> 0 | V33: 환산 | W33: =$G32*W32 -> 0 | X33: 환산 | Y33: =$G32*Y32 -> 0.37383423 | Z33: 환산 | AA33: =$G32*AA32 -> 0 | AB33: 환산 | AC33: =$G32*AC32 -> 0 | AD33: 환산 | AE33: =$G32*AE32 -> 0 | AF33: 환산 | AG33: =$G32*AG32 -> 0 | AJ33: =(I32-H32)*G32 -> 0.37383423 | AK33: =(1-I32)*G32 -> 37.009588 | AM33: 수금 | AN33: 0 | AO33: 외주처리 | AP33: =SUM(AQ33:BM33) -> 0 | AQ33: 측량 | AR33: 0 | AS33: 조경 | AT33: 0 | AU33: 조감도 | AV33: 0 | AW33: 용지 | AY33: 기타
C34: 중지: | D34: 잔액 | E34: =E32-E33 -> 108.10456 | F34: 외주 등 | G34: =(AP33+AP34)/1000000 -> 0 | J34: 진행 공정 | L34: 진행 공정 | N34: 진행 공정 | P34: 진행 공정 | R34: 진행 공정 | T34: 진행 공정 | V34: 진행 공정 | X34: 진행 공정 | Y34: 착수계제출(8/22) | Z34: 진행 공정 | AB34: 진행 공정 | AD34: 진행 공정 | AF34: 진행 공정 | AM34: 잔액 | AN34: =AN32-AN33 -> 118915020 | AO34: 기타비용
B35: 서천군 | C35: 잔여: | D35: 수금율 | E35: =E33/E32 -> 0 | F35: 수행율 | G35: =(E32-(G33+G34)/0.7)/E32 -> 0.42258285 | AH35: =(I32-E35)*E32 -> 1.0810456 | AN35: =AN33/AN32 -> 0 | AO35: 합 계 | AP35: =SUM(AP32:AP34) -> 43695000
A36: 9 | B36: 공릉관광지 조성계획(변경) 수립 용역 | C36: 17.02.07 | D36: 계약 | E36: =AN36/1100000 -> 72.36 | F36: 수행 | G36: =E36*0.75-(G37+G38) -> 17.72 | H36: 0.95 | I36: =H36+K36+M36+O36+Q36+S36+U36+W36+Y36+AA36+AC36+AE36+AG36 -> 0.95 | J36: 공정 | L36: 공정 | N36: 공정 | P36: 공정 | R36: 공정 | T36: 공정 | V36: 공정 | X36: 공정 | Z36: 공정 | AB36: 공정 | AD36: 공정 | AF36: 공정 | AH36: -용역중지(행정인가 완료시까지) -천마 경관설계 분담 완료 | AI36: 파주시 감독:강태규 / 문일형 | AJ36: 당해공정금액 | AK36: 공정잔액 | AL36: 17-01 | AM36: 계약 | AN36: 79596000 | AO36: 부서협조 | AP36: =SUM(AQ36:BM36) -> 0 | AQ36: 지반협조 | AS36: 구조협조 | AU36: 기타 | AW36: 기타 | AY36: 기타
C37: 18.12.31 | D37: 수금 | E37: =AN37/1100000 -> 68.733636 | F37: 협조 | G37: =AP36/1000000 -> 0 | J37: 환산 | K37: =$G36*K36 -> 0 | L37: 환산 | M37: =$G36*M36 -> 0 | N37: 환산 | O37: =$G36*O36 -> 0 | P37: 환산 | Q37: =$G36*Q36 -> 0 | R37: 환산 | S37: =$G36*S36 -> 0 | T37: 환산 | U37: =$G36*U36 -> 0 | V37: 환산 | W37: =$G36*W36 -> 0 | X37: 환산 | Y37: =$G36*Y36 -> 0 | Z37: 환산 | AA37: =$G36*AA36 -> 0 | AB37: 환산 | AC37: =$G36*AC36 -> 0 | AD37: 환산 | AE37: =$G36*AE36 -> 0 | AF37: 환산 | AG37: =$G36*AG36 -> 0 | AJ37: =(I36-H36)*G36 -> 0 | AK37: =(1-I36)*G36 -> 0.886 | AM37: 수금 | AN37: 75607000 | AO37: 외주처리 | AP37: =SUM(AQ37:BM37) -> 36550000 | AQ37: 경관 | AR37: 35000000 | AS37: 해외사례조사 | AT37: 1550000 | AU37: 내역 | AW37: 용지 | AY37: 기타
C38: 중지: 18.11.25 | D38: 잔액 | E38: =E36-E37 -> 3.6263636 | F38: 외주 등 | G38: =(AP37+AP38)/1000000 -> 36.55 | J38: 진행 공정 | L38: 진행 공정 | N38: 진행 공정 | P38: 진행 공정 | R38: 진행 공정 | T38: 진행 공정 | V38: 진행 공정 | W38: - | X38: 진행 공정 | Y38: - | Z38: 진행 공정 | AB38: 진행 공정 | AD38: 진행 공정 | AF38: 진행 공정 | AM38: 잔액 | AN38: =AN36-AN37 -> 3989000 | AO38: 기타비용
B39: 파주시 | C39: 잔여:36일 | D39: 수금율 | E39: =E37/E36 -> 0.94988442 | F39: 수행율 | G39: =(E36-(G37+G38)/0.7)/E36 -> 0.27840954 | AH39: =(I36-E39)*E36 -> 0.0083636364 | AN39: =AN37/AN36 -> 0.94988442 | AO39: 합 계 | AP39: =SUM(AP36:AP38) -> 36550000
A40: 10 | B40: 대부황금로 도로(자전거)확포장공사 | C40: 16.03.29 | D40: 계약 | E40: =AN40/1100000 -> 101 | F40: 수행 | G40: =E40*0.75-(G41+G42) -> 30.295455 | H40: 0.95 | I40: =H40+K40+M40+O40+Q40+S40+U40+W40+Y40+AA40+AC40+AE40+AG40 -> 0.95 | J40: 공정 | L40: 공정 | N40: 공정 | P40: 공정 | R40: 공정 | T40: 공정 | V40: 공정 | X40: 공정 | Z40: 공정 | AB40: 공정 | AD40: 공정 | AF40: 공정 | AH40: -용역중지(행정인가 완료시까지) -천마 측량분야 분담 완료 | AI40: 건설도로과 팀장:이문희 감독:김지현 / 박찬용 | AJ40: 당해공정금액 | AK40: 공정잔액 | AL40: 16-03 | AM40: 계약 | AN40: 111100000 | AO40: 부서협조 | AP40: =SUM(AQ40:BM40) -> 0 | AQ40: 지반협조 | AS40: 구조협조 | AU40: 기타 | AW40: 기타 | AY40: 기타
...

Sheet 부서협조
A1: 2. 부서협조 | G1: 부서선택 | AI1: (단위: 백만원)
A2: 순서 | B2: 사 업 명 [주관부서] | C2: 과업기간 | D2: 협조금액 | F2: 수행금액 | H2: 전년 공정 | I2: 당해 공정 | J2: 1월 공정 | L2: 2월 공정 | N2: 3월 공정 | P2: 4월 공정 | R2: 5월 공정 | T2: 6월 공정 | V2: 7월 공정 | X2: 8월 공정 | Z2: 9월 기성 | AB2: 10월 기성 | AD2: 11월 기성 | AF2: 12월 기성 | AH2: 주요보고사항 | AI2: 담당자 | AL2: JOB NO | AN2: 부가세 제외 | AP2: 부가세포함
A3: 1 | B3: 청라농공단지 조성사업 조사설계 용역 | D3: 협조 | E3: =AN3/1000000 -> 63.047667 | F3: 수행 | G3: =E3-(G4+G5) -> 13.047667 | H3: 0.7 | I3: =H3+K3+M3+O3+Q3+S3+U3+W3+Y3+AA3+AC3+AE3+AG3 -> 0.92 | J3: 공정 | K3: 0.03 | L3: 공정 | M3: 0.03 | N3: 공정 | O3: 0.03 | P3: 공정 | Q3: 0.04 | R3: 공정 | S3: 0.03 | T3: 공정 | U3: 0.02 | V3: 공정 | W3: 0.02 | X3: 공정 | Y3: 0.02 | Z3: 공정 | AB3: 공정 | AD3: 공정 | AF3: 공정 | AH3: 단지설계부 이관진행 (행정정리 필요) | AI3: 김권수이사 | AJ3: 당해공정금액 | AK3: 공정잔액 | AL3: 16-02 | AM3: 협조 | AN3: 63047667 | AP3: =SUM(AQ3:BM3) -> 0
F4: 외주 | G4: =AP4/1100000 -> 50 | J4: 환산 | K4: =$G3*K3 -> 0.39143001 | L4: 환산 | M4: =$G3*M3 -> 0.39143001 | N4: 환산 | O4: =$G3*O3 -> 0.39143001 | P4: 환산 | Q4: =$G3*Q3 -> 0.52190668 | R4: 환산 | S4: =$G3*S3 -> 0.39143001 | T4: 환산 | U4: =$G3*U3 -> 0.26095334 | V4: 환산 | W4: =$G3*W3 -> 0.26095334 | X4: 환산 | Y4: =$G3*Y3 -> 0.26095334 | Z4: 환산 | AA4: =$G3*AA3 -> 0 | AB4: 환산 | AC4: =$G3*AC3 -> 0 | AD4: 환산 | AE4: =$G3*AE3 -> 0 | AF4: 환산 | AG4: =$G3*AG3 -> 0 | AJ4: =(I3-H3)*G3 -> 2.8704867 | AK4: =(1-I3)*G3 -> 1.0438134 | AO4: 외주처리 | AP4: =SUM(AQ4:BM4) -> 55000000 | AQ4: 실시설계 | AR4: ='외주관리-부가세포함(토목부 백업)-출력X'!AQ28 -> 55000000 | AS4: 경관 | AU4: 내역 | AW4: 용지 | AY4: 기타
C5: 중지: | D5: 원사업 | F5: 기타 | G5: =AP5/1000000 -> 0 | J5: 진행 공정 | K5: 0 0 검토 0 0 산출 | L5: 진행 공정 | M5: 0 0 검토 0 0 산출 | N5: 진행 공정 | O5: 0 0 검토 0 0 산출 | P5: 진행 공정 | Q5: 0 0 검토 0 0 산출 | R5: 진행 공정 | S5: 0 0 검토 0 0 산출 | T5: 진행 공정 | U5: 재심의조치계획 | V5: 진행 공정 | W5: 재심의조치계획 | X5: 진행 공정 | Y5: 재심의조치계획 | Z5: 진행 공정 | AA5: 0 0 검토 0 0 산출 | AB5: 진행 공정 | AC5: 0 0 검토 0 0 산출 | AD5: 진행 공정 | AE5: 0 0 검토 0 0 산출 | AF5: 진행 공정 | AG5: 0 0 검토 0 0 산출 | AO5: 기타비용
B6: 도시계획부 | C6: 잔여: | D6: 수금율 | E6: 0.909 | F6: 수행율 | G6: =(E3-(G4+G5)*1.1)/E3 -> 0.12764417 | AO6: 합 계 | AP6: =SUM(AP3:AP5) -> 55000000
A7: 2 | B7: 남양주 오남3지구 도시관리계획(지구단위계획)결정(변경), 기본 및 실시설계(기반시설) 등 용역 | C7: 2015.06 | D7: 협조 | E7: =AN7/1000000 -> 45.5 | F7: 수행 | G7: =E7-(G8+G9) -> 45.5 | H7: 0 | I7: =H7+K7+M7+O7+Q7+S7+U7+W7+Y7+AA7+AC7+AE7+AG7 -> 0 | J7: 공정 | L7: 공정 | N7: 공정 | P7: 공정 | R7: 공정 | T7: 공정 | U7: 0 | V7: 공정 | W7: 0 | X7: 공정 | Y7: 0 | Z7: 공정 | AB7: 공정 | AD7: 공정 | AF7: 공정 | AH7: 진행중지중 | AI7: 김권수이사 | AJ7: 당해공정금액 | AK7: 공정잔액 | AM7: 협조 | AN7: 45500000 | AP7: =SUM(AQ7:BM7) -> 0
C8: 실시계획 인가시까지 | F8: 외주 | G8: =AP8/1100000 -> 0 | J8: 환산 | K8: =$G7*K7 -> 0 | L8: 환산 | M8: =$G7*M7 -> 0 | N8: 환산 | O8: =$G7*O7 -> 0 | P8: 환산 | Q8: =$G7*Q7 -> 0 | R8: 환산 | S8: =$G7*S7 -> 0 | T8: 환산 | U8: =$G7*U7 -> 0 | V8: 환산 | W8: =$G7*W7 -> 0 | X8: 환산 | Y8: =$G7*Y7 -> 0 | Z8: 환산 | AA8: =$G7*AA7 -> 0 | AB8: 환산 | AC8: =$G7*AC7 -> 0 | AD8: 환산 | AE8: =$G7*AE7 -> 0 | AF8: 환산 | AG8: =$G7*AG7 -> 0 | AJ8: =(I7-H7)*G7 -> 0 | AK8: =(1-I7)*G7 -> 45.5 | AO8: 외주처리 | AP8: =SUM(AQ8:BM8) -> 0 | AQ8: 교통 | AS8: 경관 | AU8: 내역 | AW8: 용지 | AY8: 기타
C9: 중지: | D9: 원사업 | F9: 기타 | G9: =AP9/1000000 -> 0 | J9: 진행 공정 | L9: 진행 공정 | N9: 진행 공정 | P9: 진행 공정 | R9: 진행 공정 | T9: 진행 공정 | V9: 진행 공정 | X9: 진행 공정 | Z9: 진행 공정 | AB9: 진행 공정 | AD9: 진행 공정 | AF9: 진행 공정 | AO9: 기타비용
B10: 도시계획부 | C10: 잔여: | D10: 수금율 | E10: 0.078 | F10: 수행율 | G10: =(E7-(G8+G9)*1.1)/E7 -> 1 | AO10: 합 계 | AP10: =SUM(AP7:AP9) -> 0
A11: 3 | B11: 화성(장안지구)공동주택 신축사업 지구단위계획 및 인허가 설계 용역 | C11: 14.05.16 | D11: 협조 | E11: =AN11/1000000 -> 175.5 | F11: 수행 | G11: =E11-(G12+G13) -> 175.5 | H11: 0.1 | I11: =H11+K11+M11+O11+Q11+S11+U11+W11+Y11+AA11+AC11+AE11+AG11 -> 0.1 | J11: 공정 | L11: 공정 | N11: 공정 | P11: 공정 | R11: 공정 | T11: 공정 | U11: 0 | V11: 공정 | W11: 0 | X11: 공정 | Y11: 0 | Z11: 공정 | AB11: 공정 | AD11: 공정 | AF11: 공정 | AH11: 진행중지중 | AI11: 김권수이사 | AJ11: 당해공정금액 | AK11: 공정잔액 | AM11: 협조 | AN11: 175500000 | AP11: =SUM(AQ11:BM11) -> 0
C12: 사업승인시 | F12: 외주 | G12: =AP12/1100000 -> 0 | J12: 환산 | K12: =$G11*K11 -> 0 | L12: 환산 | M12: =$G11*M11 -> 0 | N12: 환산 | O12: =$G11*O11 -> 0 | P12: 환산 | Q12: =$G11*Q11 -> 0 | R12: 환산 | S12: =$G11*S11 -> 0 | T12: 환산 | U12: =$G11*U11 -> 0 | V12: 환산 | W12: =$G11*W11 -> 0 | X12: 환산 | Y12: =$G11*Y11 -> 0 | Z12: 환산 | AA12: =$G11*AA11 -> 0 | AB12: 환산 | AC12: =$G11*AC11 -> 0 | AD12: 환산 | AE12: =$G11*AE11 -> 0 | AF12: 환산 | AG12: =$G11*AG11 -> 0 | AJ12: =(I11-H11)*G11 -> 0 | AK12: =(1-I11)*G11 -> 157.95 | AO12: 외주처리 | AP12: =SUM(AQ12:BM12) -> 0 | AQ12: 교통 | AS12: 경관 | AU12: 내역 | AW12: 용지 | AY12: 기타
C13: 중지: | D13: 원사업 | F13: 기타 | G13: =AP13/1000000 -> 0 | J13: 진행 공정 | L13: 진행 공정 | N13: 진행 공정 | P13: 진행 공정 | R13: 진행 공정 | T13: 진행 공정 | V13: 진행 공정 | X13: 진행 공정 | Z13: 진행 공정 | AB13: 진행 공정 | AD13: 진행 공정 | AF13: 진행 공정 | AO13: 기타비용
B14: 도시계획부 | C14: 잔여: | D14: 수금율 | E14: 0.209 | F14: 수행율 | G14: =(E11-(G12+G13)*1.1)/E11 -> 1 | AO14: 합 계 | AP14: =SUM(AP11:AP13) -> 0
A15: 계 | D15: 협조 | E15: =E3+E7+E11 -> 284.04767 | F15: 수행 | G15: =G3+G7+G11 -> 234.04767 | J15: 환산 | K15: =K4+K8+K12 -> 0.39143001 | L15: 환산 | M15: =M4+M8+M12 -> 0.39143001 | N15: 환산 | O15: =O4+O8+O12 -> 0.39143001 | P15: 환산 | Q15: =Q4+Q8+Q12 -> 0.52190668 | R15: 환산 | S15: =S4+S8+S12 -> 0.39143001 | T15: 환산 | U15: =U4+U8+U12 -> 0.26095334 | V15: 환산 | W15: =W4+W8+W12 -> 0.26095334 | X15: 환산 | Y15: =Y4+Y8+Y12 -> 0.26095334 | Z15: 환산 | AA15: =AA4+AA8+AA12 -> 0 | AB15: 환산 | AC15: =AC4+AC8+AC12 -> 0 | AD15: 환산 | AE15: =AE4+AE8+AE12 -> 0 | AF15: 환산 | AG15: =AG4+AG8+AG12 -> 0 | AJ15: 계 | AK15: 계
E16: 0 | F16: 외주 | G16: =G4+G8+G12 -> 50 | AJ16: =SUM(AJ3:AJ14) -> 2.8704867 | AK16: =SUM(AK3:AK14) -> 204.49381
E17: 0 | F17: 기타 | G17: =G5+G9+G13 -> 0
E18: 0 | F18: 수행율 | G18: =(E15-(G16+G17)/0.7)/E15 -> 0.74853315

Sheet 일괄외주관리(없음)-출력X
A1: 3. 외주관리 | AI1: (단위: 백만원)
A2: 순서 | B2: 사 업 명 [주관부서] | C2: 과업기간 | D2: 금액현황 | F2: 외주금액 | H2: 전년 공정 | I2: 당해 공정 | J2: 1월 공정 | L2: 2월 공정 | N2: 3월 공정 | P2: 4월 공정 | R2: 5월 공정 | T2: 6월 공정 | V2: 7월 공정 | X2: 8월 공정 | Z2: 9월 기성 | AB2: 10월 기성 | AD2: 11월 기성 | AF2: 12월 기성 | AH2: 주요사항/처리업체 | AI2: 발주처/ 담당자 | AK2: JOB NO
A3: 0 | T3: 공정 | U3: 0.02 | AL3: 계약
T4: x | U4: x | AL4: 수금
T5: 진행 공정 | U5: 재심의조치계획 | AL5: 잔액
A7: 0 | AL7: 계약
AL8: 수금
AL9: 잔액
A11: 0 | AL11: 계약
AL12: 수금
AL13: 잔액
A15: 0
A19: 계 | D19: 계약 | E19: =E3+E7+E11 -> 0 | F19: 외주 | G19: =G3+G7+G11 -> 0 | J19: 공정 | L19: 공정 | N19: 공정 | P19: 공정 | R19: 공정 | X19: 공정 | Z19: 공정 | AB19: 공정 | AD19: 공정 | AF19: 공정
D20: 수금 | E20: =E4+E8+E12 -> 0 | F20: 지급 | G20: =G4+G8+G12 -> 0 | J20: 환산 | K20: 0 | L20: 환산 | M20: 0 | N20: 환산 | O20: 0 | P20: 환산 | Q20: 0 | R20: 환산 | S20: 0 | X20: 환산 | Y20: 0 | Z20: 환산 | AA20: 0 | AB20: 환산 | AC20: 0 | AD20: 환산 | AE20: 0 | AF20: 환산 | AG20: 0
D21: 잔액 | E21: =E5+E9+E13 -> 0 | F21: 잔액 | G21: =G5+G9+G13 -> 0 | J21: 진행 공정 | L21: 진행 공정 | N21: 진행 공정 | P21: 진행 공정 | R21: 진행 공정 | X21: 진행 공정 | Z21: 진행 공정 | AB21: 진행 공정 | AD21: 진행 공정 | AF21: 진행 공정
D22: 수금율 | F22: 외주 율

Sheet 외주관리-부가세포함(토목부 백업)-출력X
A1: 3. 외주관리 | AI1: (단위: 백만원)
A2: 순서 | B2: 사 업 명 [주관부서] | C2: 과업기간 | D2: 금액현황 | F2: 외주금액 | H2: 전년 공정 | I2: 당해 공정 | J2: 1월 공정 | L2: 2월 공정 | N2: 3월 공정 | P2: 4월 공정 | R2: 5월 공정 | T2: 6월 공정 | V2: 7월 공정 | X2: 8월 공정 | Z2: 9월 기성 | AB2: 10월 기성 | AD2: 11월 기성 | AF2: 12월 기성 | AH2: 주요사항/처리업체 | AI2: 발주처/ 담당자 | AK2: JOB NO | AM2: 부가세 포함
A3: 1 | B3: 창동복합공연장 민간투자사업 건립공사 | C3: 11.06.22 | D3: 계약 | E3: =AM3/1100000 -> 100 | F3: 외주 | G3: =AO4/1100000 -> 20 | H3: 1 | I3: =H3+K3+M3+O3+Q3+S3+U3+W3+Y3+AA3+AC3+AE3+AG3 -> 1 | J3: 공정 | L3: 공정 | N3: 공정 | P3: 공정 | R3: 공정 | T3: 공정 | V3: 공정 | X3: 공정 | Z3: 공정 | AB3: 공정 | AD3: 공정 | AF3: 공정 | AH3: 행정소송결과에 따른 잔액 미수금(외주비처리 여부 확인必) /미강엔지니어링 ㈜웹솔루스 | AL3: 계약 | AM3: 110000000 | AO3: =SUM(AP3:BL3) -> 0
C4: 11.07.30 | D4: 수금 | E4: =AM4/1100000 -> 50 | F4: 지급 | G4: =AO5/1100000 -> 7.5 | J4: 환산 | K4: =$G3*K3 -> 0 | L4: 환산 | M4: =$G3*M3 -> 0 | N4: 환산 | O4: =$G3*O3 -> 0 | P4: 환산 | Q4: =$G3*Q3 -> 0 | R4: 환산 | S4: =$G3*S3 -> 0 | T4: 환산 | U4: =$G3*U3 -> 0 | W4: =$G3*W3 -> 0 | Z4: 환산 | AA4: =$G3*AA3 -> 0 | AB4: 환산 | AC4: =$G3*AC3 -> 0 | AD4: 환산 | AE4: =$G3*AE3 -> 0 | AF4: 환산 | AG4: =$G3*AG3 -> 0 | AL4: 수금 | AM4: 55000000 | AN4: 외주처리 | AO4: =SUM(AP4:BL4) -> 22000000 | AP4: 구조물1식 | AQ4: 5500000 | AR4: 암거내수리검토 | AS4: 16500000 | AT4: 상하수도 | AV4: 아르바이트 | AX4: 아르바이트
C5: 중지: | D5: 잔액 | E5: =E3-E4 -> 50 | F5: 잔액 | G5: =G3-G4 -> 12.5 | J5: 진행 공정 | K5: 0 0 검토 0 0 산출 | L5: 진행 공정 | M5: 0 0 검토 0 0 산출 | N5: 진행 공정 | O5: 0 0 검토 0 0 산출 | P5: 진행 공정 | Q5: 0 0 검토 0 0 산출 | R5: 진행 공정 | S5: 0 0 검토 0 0 산출 | T5: 진행 공정 | U5: 준공 | V5: 진행 공정 | W5: 준공 | X5: 진행 공정 | Z5: 진행 공정 | AA5: 0 0 검토 0 0 산출 | AB5: 진행 공정 | AC5: 0 0 검토 0 0 산출 | AD5: 진행 공정 | AE5: 0 0 검토 0 0 산출 | AF5: 진행 공정 | AG5: 0 0 검토 0 0 산출 | AL5: 잔액 | AM5: =AM3-AM4 -> 55000000 | AN5: 지급 | AO5: =SUM(AP5:BL5) -> 8250000 | AS5: 8250000
B6: 엠큐브시어터 | C6: 잔여: | D6: 수금율 | E6: =E4/E3 -> 0.5 | F6: 외주 율 | G6: =G3/E3 -> 0.2 | AH6: =(I3-E6)*E3 -> 50 | AM6: =AM4/AM3 -> 0.5 | AN6: 잔액 | AO6: =AO4-AO5 -> 13750000
A7: 2 | B7: 대부동 서남부 연결도로 개설공사 실시설계 용역 | C7: 09.04.17 | D7: 계약 | E7: =AM7/1100000 -> 267.63182 | F7: 외주 | G7: =AO8/1100000 -> 99.606136 | H7: 0.9 | I7: =H7+K7+M7+O7+Q7+S7+U7+W7+Y7+AA7+AC7+AE7+AG7 -> 1 | J7: 공정 | K7: 0.1 | L7: 공정 | N7: 공정 | P7: 공정 | R7: 공정 | T7: 공정 | V7: 공정 | X7: 공정 | Z7: 공정 | AB7: 공정 | AD7: 공정 | AF7: 공정 | AH7: 제니스이엔씨㈜ ㈜미동엔지니어링 ㈜나우엔지니어링 박성삼 엄성곤 ㈜대영설계측량 ㈜제네시스엔지니어링 ㈜용마엔지니어링 | AL7: 계약 | AM7: 294395000 | AO7: =SUM(AP7:BL7) -> 0
C8: 19.02.25 | D8: 수금 | E8: =AM8/1100000 -> 267.63182 | F8: 지급 | G8: =AO9/1100000 -> 30.462045 | J8: 환산 | K8: =$G7*K7 -> 9.9606136 | L8: 환산 | M8: =$G7*M7 -> 0 | N8: 환산 | O8: =$G7*O7 -> 0 | P8: 환산 | Q8: =$G7*Q7 -> 0 | R8: 환산 | S8: =$G7*S7 -> 0 | T8: 환산 | U8: =$G7*U7 -> 0 | W8: =$G7*W7 -> 0 | Z8: 환산 | AA8: =$G7*AA7 -> 0 | AB8: 환산 | AC8: =$G7*AC7 -> 0 | AD8: 환산 | AE8: =$G7*AE7 -> 0 | AF8: 환산 | AG8: =$G7*AG7 -> 0 | AL8: 수금 | AM8: =AM7 -> 294395000 | AN8: 외주처리 | AO8: =SUM(AP8:BL8) -> 109566750 | AP8: 측량 | AQ8: 11930000 | AR8: 환경성검토 | AS8: 10481000 | AT8: 전기 | AU8: 3547500 | AV8: 사전재해영향성 | AW8: 8100000 | AX8: 산림조사서 | AY8: 3025000 | AZ8: 수리수문분석 | BA8: 1500000 | BB8: 상하수도 | BC8: 8500000 | BD8: 해역이용협의 | BE8: 33000000 | BF8: 문화재지표조사 | BG8: =2257500+225750 -> 2483250 | BH8: 양남감포아르바이트 | BI8: =4545455+454545 -> 5000000 | BJ8: 실시계획인가(변경) | BK8: 22000000
C9: 중지: | D9: 잔액 | E9: =E7-E8 -> 0 | F9: 잔액 | G9: =G7-G8 -> 69.144091 | J9: 진행 공정 | K9: 0 0 검토 0 0 산출 | L9: 진행 공정 | M9: 0 0 검토 0 0 산출 | N9: 진행 공정 | O9: 0 0 검토 0 0 산출 | P9: 진행 공정 | Q9: 0 0 검토 0 0 산출 | R9: 진행 공정 | S9: 0 0 검토 0 0 산출 | T9: 진행 공정 | U9: 준공 | V9: 진행 공정 | W9: 준공 | X9: 진행 공정 | Z9: 진행 공정 | AA9: 0 0 검토 0 0 산출 | AB9: 진행 공정 | AC9: 0 0 검토 0 0 산출 | AD9: 진행 공정 | AE9: 0 0 검토 0 0 산출 | AF9: 진행 공정 | AG9: 0 0 검토 0 0 산출 | AL9: 잔액 | AM9: =AM7-AM8 -> 0 | AN9: 지급 | AO9: =SUM(AP9:BL9) -> 33508250 | AY9: 3025000 | BE9: 23000000 | BG9: 2483250 | BI9: 5000000
B10: 안산시 | C10: 잔여: | D10: 수금율 | E10: =E8/E7 -> 1 | F10: 외주 율 | G10: =G7/E7 -> 0.37217599 | AH10: =(I7-E10)*E7 -> 0 | AM10: =AM8/AM7 -> 1 | AN10: 잔액 | AO10: =AO8-AO9 -> 76058500
A11: 3 | B11: 선도지구 지방관리방조제 개보수사업 실시설계 | C11: 13.10.28 | D11: 계약 | E11: =AM11/1100000 -> 8.2 | F11: 외주 | G11: =AO12/1100000 -> 0.90909091 | H11: 1 | I11: =H11+K11+M11+O11+Q11+S11+U11+W11+Y11+AA11+AC11+AE11+AG11 -> 1 | J11: 공정 | L11: 공정 | N11: 공정 | P11: 공정 | R11: 공정 | T11: 공정 | V11: 공정 | X11: 공정 | Z11: 공정 | AB11: 공정 | AD11: 공정 | AF11: 공정 | AH11: 이하익 전력본부장 퇴사시 외주비 정리 확인必 /임순향(전기) | AL11: 계약 | AM11: 9020000 | AO11: =SUM(AP11:BL11) -> 0
C12: 14.12.16 | D12: 수금 | E12: =AM12/1100000 -> 8.2 | F12: 지급 | G12: =AO13/1100000 -> 0 | J12: 환산 | K12: =$G11*K11 -> 0 | L12: 환산 | M12: =$G11*M11 -> 0 | N12: 환산 | O12: =$G11*O11 -> 0 | P12: 환산 | Q12: =$G11*Q11 -> 0 | R12: 환산 | S12: =$G11*S11 -> 0 | T12: 환산 | U12: =$G11*U11 -> 0 | W12: =$G11*W11 -> 0 | Z12: 환산 | AA12: =$G11*AA11 -> 0 | AB12: 환산 | AC12: =$G11*AC11 -> 0 | AD12: 환산 | AE12: =$G11*AE11 -> 0 | AF12: 환산 | AG12: =$G11*AG11 -> 0 | AL12: 수금 | AM12: =AM11 -> 9020000 | AN12: 외주처리 | AO12: =SUM(AP12:BL12) -> 1000000 | AP12: 전기 | AQ12: 1000000 | AR12: 암거내수리검토 | AT12: 상하수도 | AV12: 아르바이트 | AX12: 아르바이트
C13: 중지: | D13: 잔액 | E13: =E11-E12 -> 0 | F13: 잔액 | G13: =G11-G12 -> 0.90909091 | J13: 진행 공정 | K13: 0 0 검토 0 0 산출 | L13: 진행 공정 | M13: 0 0 검토 0 0 산출 | N13: 진행 공정 | O13: 0 0 검토 0 0 산출 | P13: 진행 공정 | Q13: 0 0 검토 0 0 산출 | R13: 진행 공정 | S13: 0 0 검토 0 0 산출 | T13: 진행 공정 | U13: 준공 | V13: 진행 공정 | W13: 준공 | X13: 진행 공정 | Z13: 진행 공정 | AA13: 0 0 검토 0 0 산출 | AB13: 진행 공정 | AC13: 0 0 검토 0 0 산출 | AD13: 진행 공정 | AE13: 0 0 검토 0 0 산출 | AF13: 진행 공정 | AG13: 0 0 검토 0 0 산출 | AL13: 잔액 | AM13: =AM11-AM12 -> 0 | AN13: 지급 | AO13: =SUM(AP13:BL13) -> 0
B14: 서천군 | C14: 잔여: | D14: 수금율 | E14: =E12/E11 -> 1 | F14: 외주 율 | G14: =G11/E11 -> 0.11086475 | AH14: =(I11-E14)*E11 -> 0 | AM14: =AM12/AM11 -> 1 | AN14: 잔액 | AO14: =AO12-AO13 -> 1000000
A15: 4 | B15: 평택3복합화력 EPC건설공사 입찰 설계 용역 | C15: 14.08.01 | D15: 계약 | E15: =AM15/1100000 -> 5 | F15: 외주 | G15: =AO16/1100000 -> 0.8 | H15: 1 | I15: =H15+K15+M15+O15+Q15+S15+U15+W15+Y15+AA15+AC15+AE15+AG15 -> 1 | J15: 공정 | L15: 공정 | N15: 공정 | P15: 공정 | R15: 공정 | T15: 공정 | V15: 공정 | X15: 공정 | Z15: 공정 | AB15: 공정 | AD15: 공정 | AF15: 공정 | AH15: 이하익 전력본부장 퇴사시 외주비 정리 확인必 /임순향(전기) | AL15: 계약 | AM15: 5500000 | AN15: 미동엔지니어링 | AO15: =SUM(AP15:BL15) -> 0
C16: 14.11.14 | D16: 수금 | E16: =AM16/1100000 -> 5 | F16: 지급 | G16: =AO17/1100000 -> 0 | J16: 환산 | K16: =$G15*K15 -> 0 | L16: 환산 | M16: =$G15*M15 -> 0 | N16: 환산 | O16: =$G15*O15 -> 0 | P16: 환산 | Q16: =$G15*Q15 -> 0 | R16: 환산 | S16: =$G15*S15 -> 0 | T16: 환산 | U16: =$G15*U15 -> 0 | W16: =$G15*W15 -> 0 | Z16: 환산 | AA16: =$G15*AA15 -> 0 | AB16: 환산 | AC16: =$G15*AC15 -> 0 | AD16: 환산 | AE16: =$G15*AE15 -> 0 | AF16: 환산 | AG16: =$G15*AG15 -> 0 | AL16: 수금 | AM16: 5500000 | AN16: 외주처리 | AO16: =SUM(AP16:BL16) -> 880000 | AP16: 전기 | AQ16: 880000 | AR16: 암거내수리검토 | AT16: 상하수도 | AV16: 아르바이트 | AX16: 아르바이트
C17: 중지: | D17: 잔액 | E17: =E15-E16 -> 0 | F17: 잔액 | G17: =G15-G16 -> 0.8 | J17: 진행 공정 | K17: 0 0 검토 0 0 산출 | L17: 진행 공정 | M17: 0 0 검토 0 0 산출 | N17: 진행 공정 | O17: 0 0 검토 0 0 산출 | P17: 진행 공정 | Q17: 0 0 검토 0 0 산출 | R17: 진행 공정 | S17: 0 0 검토 0 0 산출 | T17: 진행 공정 | U17: 준공 | V17: 진행 공정 | W17: 준공 | X17: 진행 공정 | Z17: 진행 공정 | AA17: 0 0 검토 0 0 산출 | AB17: 진행 공정 | AC17: 0 0 검토 0 0 산출 | AD17: 진행 공정 | AE17: 0 0 검토 0 0 산출 | AF17: 진행 공정 | AG17: 0 0 검토 0 0 산출 | AL17: 잔액 | AM17: =AM15-AM16 -> 0 | AN17: 지급 | AO17: =SUM(AP17:BL17) -> 0
B18: 미동엔지니어링 | C18: 잔여: | D18: 수금율 | E18: =E16/E15 -> 1 | F18: 외주 율 | G18: =G15/E15 -> 0.16 | AH18: =(I15-E18)*E15 -> 0 | AM18: =AM16/AM15 -> 1 | AN18: 잔액 | AO18: =AO16-AO17 -> 880000
A19: 5 | B19: 생활관 개수 등 2건 설계(14-북2-육-37) | C19: 14.09.16 | D19: 계약 | E19: =AM19/1100000 -> 9.2536364 | F19: 외주 | G19: =AO20/1100000 -> 1.8181818 | H19: 1 | I19: =H19+K19+M19+O19+Q19+S19+U19+W19+Y19+AA19+AC19+AE19+AG19 -> 1 | J19: 공정 | L19: 공정 | N19: 공정 | P19: 공정 | R19: 공정 | T19: 공정 | V19: 공정 | X19: 공정 | Z19: 공정 | AB19: 공정 | AD19: 공정 | AF19: 공정 | AH19: 이하익 전력본부장 퇴사시 외주비 정리 확인必 /박진우(전기) | AL19: 계약 | AM19: 10179000 | AO19: =SUM(AP19:BL19) -> 0
C20: 14.11.14 | D20: 수금 | E20: =AM20/1100000 -> 9.2536364 | F20: 지급 | G20: =AO21/1100000 -> 0 | J20: 환산 | K20: =$G19*K19 -> 0 | L20: 환산 | M20: =$G19*M19 -> 0 | N20: 환산 | O20: =$G19*O19 -> 0 | P20: 환산 | Q20: =$G19*Q19 -> 0 | R20: 환산 | S20: =$G19*S19 -> 0 | T20: 환산 | U20: =$G19*U19 -> 0 | W20: =$G19*W19 -> 0 | Z20: 환산 | AA20: =$G19*AA19 -> 0 | AB20: 환산 | AC20: =$G19*AC19 -> 0 | AD20: 환산 | AE20: =$G19*AE19 -> 0 | AF20: 환산 | AG20: =$G19*AG19 -> 0 | AL20: 수금 | AM20: =AM19 -> 10179000 | AN20: 외주처리 | AO20: =SUM(AP20:BL20) -> 2000000 | AP20: 전기단가 | AQ20: 2000000 | AR20: 암거내수리검토 | AT20: 상하수도 | AV20: 아르바이트 | AX20: 아르바이트
C21: 중지: | D21: 잔액 | E21: =E19-E20 -> 0 | F21: 잔액 | G21: =G19-G20 -> 1.8181818 | J21: 진행 공정 | K21: 0 0 검토 0 0 산출 | L21: 진행 공정 | M21: 0 0 검토 0 0 산출 | N21: 진행 공정 | O21: 0 0 검토 0 0 산출 | P21: 진행 공정 | Q21: 0 0 검토 0 0 산출 | R21: 진행 공정 | S21: 0 0 검토 0 0 산출 | T21: 진행 공정 | U21: 준공 | V21: 진행 공정 | W21: 준공 | X21: 진행 공정 | Z21: 진행 공정 | AA21: 0 0 검토 0 0 산출 | AB21: 진행 공정 | AC21: 0 0 검토 0 0 산출 | AD21: 진행 공정 | AE21: 0 0 검토 0 0 산출 | AF21: 진행 공정 | AG21: 0 0 검토 0 0 산출 | AL21: 잔액 | AM21: =AM19-AM20 -> 0 | AN21: 지급 | AO21: =SUM(AP21:BL21) -> 0
B22: 제7821부대 | C22: 잔여: | D22: 수금율 | E22: =E20/E19 -> 1 | F22: 외주 율 | G22: =G19/E19 -> 0.19648296 | AH22: =(I19-E22)*E19 -> 0 | AM22: =AM20/AM19 -> 1 | AN22: 잔액 | AO22: =AO20-AO21 -> 2000000
A23: 6 | B23: 대부황금로 도로(자전거)확포장공사 | C23: 16.03.29 | D23: 계약 | E23: =AM23/1100000 -> 101 | F23: 외주 | G23: =AO24/1100000 -> 45.454545 | H23: 0.95 | I23: =H23+K23+M23+O23+Q23+S23+U23+W23+Y23+AA23+AC23+AE23+AG23 -> 0.95 | J23: 공정 | L23: 공정 | N23: 공정 | P23: 공정 | R23: 공정 | T23: 공정 | V23: 공정 | X23: 공정 | Z23: 공정 | AB23: 공정 | AD23: 공정 | AF23: 공정 | AH23: ㈜대영설계측량 | AI23: 건설도로과 팀장:이문희 감독:김지현 / 박찬용 | AK23: 16-03 | AL23: 계약 | AM23: 111100000 | AN23: 부서협조 | AO23: =SUM(AP23:BL23) -> 0 | AP23: 지반협조 | AR23: 구조협조 | AT23: 기타 | AV23: 기타 | AX23: 기타
C24: 18.10.14 | D24: 수금 | E24: =AM24/1100000 -> 70.7 | F24: 지급 | G24: =AO25/1100000 -> 18.181818 | J24: 환산 | K24: =$G23*K23 -> 0 | L24: 환산 | M24: =$G23*M23 -> 0 | N24: 환산 | O24: =$G23*O23 -> 0 | P24: 환산 | Q24: =$G23*Q23 -> 0 | R24: 환산 | S24: =$G23*S23 -> 0 | T24: 환산 | U24: =$G23*U23 -> 0 | W24: =$G23*W23 -> 0 | Z24: 환산 | AA24: =$G23*AA23 -> 0 | AB24: 환산 | AC24: =$G23*AC23 -> 0 | AD24: 환산 | AE24: =$G23*AE23 -> 0 | AF24: 환산 | AG24: =$G23*AG23 -> 0 | AL24: 수금 | AM24: 77770000 | AN24: 외주처리 | AO24: =SUM(AP24:BL24) -> 50000000 | AP24: 측량 | AQ24: 50000000 | AR24: 하천설계 | AT24: 상하수도 | AV24: 아르바이트 | AX24: 아르바이트
C25: 중지: 18.10.04 | D25: 잔액 | E25: =E23-E24 -> 30.3 | F25: 잔액 | G25: =G23-G24 -> 27.272727 | J25: 진행 공정 | K25: 0 0 검토 0 0 산출 | L25: 진행 공정 | M25: 0 0 검토 0 0 산출 | N25: 진행 공정 | O25: 0 0 검토 0 0 산출 | P25: 진행 공정 | Q25: 0 0 검토 0 0 산출 | R25: 진행 공정 | S25: 0 0 검토 0 0 산출 | T25: 진행 공정 | U25: 용역중지 | V25: 진행 공정 | W25: 용역중지 | X25: 진행 공정 | Z25: 진행 공정 | AA25: 0 0 검토 0 0 산출 | AB25: 진행 공정 | AC25: 0 0 검토 0 0 산출 | AD25: 진행 공정 | AE25: 0 0 검토 0 0 산출 | AF25: 진행 공정 | AG25: 0 0 검토 0 0 산출 | AL25: 잔액 | AM25: =AM23-AM24 -> 33330000 | AN25: 지급 | AO25: =SUM(AP25:BL25) -> 20000000 | AQ25: 20000000
B26: 안산시 | C26: 잔여:11일 | D26: 수금율 | E26: =E24/E23 -> 0.7 | F26: 외주 율 | G26: =G23/E23 -> 0.450045 | AH26: =(I23-E26)*E23 -> 25.25 | AM26: =AM24/AM23 -> 0.7 | AN26: 잔액 | AO26: =AO24-AO25 -> 30000000
A27: 7 | B27: 청라농공단지 조성사업 조사설계 용역 | C27: 15.01.07 | D27: 계약 | E27: =AM27/1100000 -> 235.73182 | F27: 외주 | G27: =AO28/1100000 -> 50 | H27: =부서협조!H3 -> 0.7 | I27: =H27+K27+M27+O27+Q27+S27+U27+W27+Y27+AA27+AC27+AE27+AG27 -> 0.84 | J27: 공정 | L27: 공정 | N27: 공정 | P27: 공정 | R27: 공정 | T27: 공정 | U27: 0.1 | V27: 공정 | W27: =부서협조!W3 -> 0.02 | X27: 공정 | Y27: =부서협조!Y3 -> 0.02 | Z27: 공정 | AB27: 공정 | AD27: 공정 | AF27: 공정 | AH27: 정인컨설턴트 | AI27: 단지부 이관 진행 | AL27: 계약 | AM27: 259305000 | AO27: =SUM(AP27:BL27) -> 0
C28: 15.11.02 | D28: 수금 | E28: =AM28/1100000 -> 214.21636 | F28: 지급 | G28: =AO29/1100000 -> 15.454545 | J28: 환산 | K28: =$G27*K27 -> 0 | L28: 환산 | M28: =$G27*M27 -> 0 | N28: 환산 | O28: =$G27*O27 -> 0 | P28: 환산 | Q28: =$G27*Q27 -> 0 | R28: 환산 | S28: =$G27*S27 -> 0 | T28: 환산 | U28: =$G27*U27 -> 5 | W28: =$G27*W27 -> 1 | Z28: 환산 | AA28: =$G27*AA27 -> 0 | AB28: 환산 | AC28: =$G27*AC27 -> 0 | AD28: 환산 | AE28: =$G27*AE27 -> 0 | AF28: 환산 | AG28: =$G27*AG27 -> 0 | AL28: 수금 | AM28: 235638000 | AN28: 외주처리 | AO28: =SUM(AP28:BL28) -> 55000000 | AP28: 실시설계 | AQ28: 55000000 | AR28: 암거내수리검토 | AT28: 상하수도 | AV28: 아르바이트 | AX28: 아르바이트
C29: 중지: | D29: 잔액 | E29: =E27-E28 -> 21.515455 | F29: 잔액 | G29: =G27-G28 -> 34.545455 | J29: 진행 공정 | K29: 0 0 검토 0 0 산출 | L29: 진행 공정 | M29: 0 0 검토 0 0 산출 | N29: 진행 공정 | O29: 0 0 검토 0 0 산출 | P29: 진행 공정 | Q29: 0 0 검토 0 0 산출 | R29: 진행 공정 | S29: 0 0 검토 0 0 산출 | T29: 진행 공정 | U29: =부서협조!U5 -> 재심의조치계획 | V29: 진행 공정 | W29: =부서협조!W5 -> 재심의조치계획 | X29: 진행 공정 | Y29: =부서협조!Y5 -> 재심의조치계획 | Z29: 진행 공정 | AA29: 0 0 검토 0 0 산출 | AB29: 진행 공정 | AC29: 0 0 검토 0 0 산출 | AD29: 진행 공정 | AE29: 0 0 검토 0 0 산출 | AF29: 진행 공정 | AG29: 0 0 검토 0 0 산출 | AL29: 잔액 | AM29: =AM27-AM28 -> 23667000 | AN29: 지급 | AO29: =SUM(AP29:BL29) -> 17000000 | AQ29: 17000000
B30: 보령시 | C30: 잔여: | D30: 수금율 | E30: =E28/E27 -> 0.9087291 | F30: 외주 율 | G30: =G27/E27 -> 0.21210544 | AH30: =(I27-E30)*E27 -> -16.201636 | AM30: =AM28/AM27 -> 0.9087291 | AN30: 잔액 | AO30: =AO28-AO29 -> 38000000
A31: 8 | B31: 용인 역삼구역 도시개발사업 실시설계(변경) 용역 | C31: 16.08.01 | D31: 계약 | E31: =AM31/1100000 -> 2348 | F31: 외주 | G31: =AO32/1100000 -> 224.69091 | H31: 0.9 | I31: =H31+K31+M31+O31+Q31+S31+U31+W31+Y31+AA31+AC31+AE31+AG31 -> 0.9 | J31: 공정 | L31: 공정 | N31: 공정 | P31: 공정 | R31: 공정 | T31: 공정 | V31: 공정 | X31: 공정 | Z31: 공정 | AB31: 공정 | AD31: 공정 | AF31: 공정 | AH31: 영흥이엔지 수하이엔택 정인컨설턴트 채경호계약직 김명훈,배현 | AI31: 역삼조합 조합장:정동춘 국장:김기두 / 문일형,김대영,주성완,박찬용,박민규,최진현 | AL31: 계약 | AM31: 2582800000 | AO31: =SUM(AP31:BL31) -> 0
C32: 17.12.31 (완료시) | D32: 수금 | E32: =AM32/1100000 -> 436.36364 | F32: 지급 | G32: =AO33/1100000 -> 68.214176 | J32: 환산 | K32: =$G31*K31 -> 0 | L32: 환산 | M32: =$G31*M31 -> 0 | N32: 환산 | O32: =$G31*O31 -> 0 | P32: 환산 | Q32: =$G31*Q31 -> 0 | R32: 환산 | S32: =$G31*S31 -> 0 | T32: 환산 | U32: =$G31*U31 -> 0 | W32: =$G31*W31 -> 0 | Z32: 환산 | AA32: =$G31*AA31 -> 0 | AB32: 환산 | AC32: =$G31*AC31 -> 0 | AD32: 환산 | AE32: =$G31*AE31 -> 0 | AF32: 환산 | AG32: =$G31*AG31 -> 0 | AL32: 수금 | AM32: 480000000 | AN32: 외주처리 | AO32: =SUM(AP32:BL32) -> 247160000 | AP32: 측량 | AQ32: 55000000 | AR32: 하천설계 | AS32: 66000000 | AT32: 상하수도 | AU32: 93500000 | AV32: 아르바이트 | AW32: 21000000 | AX32: 아르바이트 | AY32: 11660000
C33: 중지: 18.10.04 | D33: 잔액 | E33: =E31-E32 -> 1911.6364 | F33: 잔액 | G33: =G31-G32 -> 156.47673 | J33: 진행 공정 | K33: 0 0 검토 0 0 산출 | L33: 진행 공정 | M33: 0 0 검토 0 0 산출 | N33: 진행 공정 | O33: 0 0 검토 0 0 산출 | P33: 진행 공정 | Q33: 0 0 검토 0 0 산출 | R33: 진행 공정 | S33: 0 0 검토 0 0 산출 | T33: 진행 공정 | U33: 용역중지 | V33: 진행 공정 | W33: 용역중지 | X33: 진행 공정 | Z33: 진행 공정 | AA33: 0 0 검토 0 0 산출 | AB33: 진행 공정 | AC33: 0 0 검토 0 0 산출 | AD33: 진행 공정 | AE33: 0 0 검토 0 0 산출 | AF33: 진행 공정 | AG33: 0 0 검토 0 0 산출 | AL33: 잔액 | AM33: =AM31-AM32 -> 2102800000 | AN33: 지급 | AO33: =SUM(AP33:BL33) -> 75035594 | AQ33: 14375594 | AU33: 28000000 | AW33: 21000000 | AY33: 11660000
B34: 용인역삼도시개발사업조합 | C34: 잔여: | D34: 수금율 | E34: =E32/E31 -> 0.18584482 | F34: 외주 율 | G34: =G31/E31 -> 0.095694595 | AH34: =(I31-E34)*E31 -> 1676.8364 | AM34: =AM32/AM31 -> 0.18584482 | AN34: 잔액 | AO34: =AO32-AO33 -> 172124406
A35: 9 | B35: 용인 역삼구역 하수처리장 건설공사 기본 및 실시설계 용역 | C35: 16.08.01 | D35: 계약 | E35: =AM35/1100000 -> 416.09091 | F35: 외주 | G35: =AO36/1100000 -> 200 | H35: 0.3 | I35: =H35+K35+M35+O35+Q35+S35+U35+W35+Y35+AA35+AC35+AE35+AG35 -> 0.3 | J35: 공정 | L35: 공정 | N35: 공정 | P35: 공정 | R35: 공정 | T35: 공정 | V35: 공정 | X35: 공정 | Z35: 공정 | AB35: 공정 | AD35: 공정 | AF35: 공정 | AH35: 준영이엔씨 에이치알이엔씨 | AI35: 역삼조합 조합장:정동춘 국장:김기두 / 문일형,김대영,박민규 | AL35: 계약 | AM35: 457700000 | AO35: =SUM(AP35:BL35) -> 0
C36: 16.12.31 (완료시) | D36: 수금 | E36: =AM36/1100000 -> 156.73455 | F36: 지급 | G36: =AO37/1100000 -> 37.7 | J36: 환산 | K36: =$G35*K35 -> 0 | L36: 환산 | M36: =$G35*M35 -> 0 | N36: 환산 | O36: =$G35*O35 -> 0 | P36: 환산 | Q36: =$G35*Q35 -> 0 | R36: 환산 | S36: =$G35*S35 -> 0 | T36: 환산 | U36: =$G35*U35 -> 0 | W36: =$G35*W35 -> 0 | Z36: 환산 | AA36: =$G35*AA35 -> 0 | AB36: 환산 | AC36: =$G35*AC35 -> 0 | AD36: 환산 | AE36: =$G35*AE35 -> 0 | AF36: 환산 | AG36: =$G35*AG35 -> 0 | AL36: 수금 | AM36: 172408000 | AN36: 외주처리 | AO36: =SUM(AP36:BL36) -> 220000000 | AP36: 전기, 통신 | AQ36: 110000000 | AR36: 조경 | AS36: 110000000 | AT36: 내역 | AV36: 용지 | AX36: 기타
C37: 중지: 18.10.01 | D37: 잔액 | E37: =E35-E36 -> 259.35636 | F37: 잔액 | G37: =G35-G36 -> 162.3 | J37: 진행 공정 | L37: 진행 공정 | N37: 진행 공정 | P37: 진행 공정 | R37: 진행 공정 | T37: 진행 공정 | U37: 용역중지 | V37: 진행 공정 | W37: 용역중지 | X37: 진행 공정 | Z37: 진행 공정 | AB37: 진행 공정 | AD37: 진행 공정 | AF37: 진행 공정 | AL37: 잔액 | AM37: =AM35-AM36 -> 285292000 | AN37: 지급 | AO37: =SUM(AP37:BL37) -> 41470000 | AQ37: 41470000
B38: 용인역삼도시개발사업조합 | C38: 잔여: | D38: 수금율 | E38: =E36/E35 -> 0.37668342 | F38: 외주 율 | G38: =G35/E35 -> 0.48066419 | AH38: =(I35-E38)*E35 -> -31.907273 | AM38: =AM36/AM35 -> 0.37668342 | AN38: 잔액 | AO38: =AO36-AO37 -> 178530000
A39: 10 | B39: 용인 역삼구역 금학천 하천기본계획검토용역 | C39: 16.11.01 | D39: 계약 | E39: =AM39/1100000 -> 177.81818 | F39: 외주 | G39: =AO40/1100000 -> 60 | H39: 0.6 | I39: =H39+K39+M39+O39+Q39+S39+U39+W39+Y39+AA39+AC39+AE39+AG39 -> 0.6 | J39: 공정 | L39: 공정 | N39: 공정 | P39: 공정 | R39: 공정 | T39: 공정 | V39: 공정 | X39: 공정 | Z39: 공정 | AB39: 공정 | AD39: 공정 | AF39: 공정 | AH39: 수하이엔택 | AI39: 역삼조합 조합장:정동춘 국장:김기두 / 문일형,김대영,박민규 | AL39: 계약 | AM39: 195600000 | AO39: =SUM(AP39:BL39) -> 0
C40: 17.07.31 | D40: 수금 | E40: =AM40/1100000 -> 17.727273 | F40: 지급 | G40: =AO41/1100000 -> 6 | J40: 환산 | K40: =$G39*K39 -> 0 | L40: 환산 | M40: =$G39*M39 -> 0 | N40: 환산 | O40: =$G39*O39 -> 0 | P40: 환산 | Q40: =$G39*Q39 -> 0 | R40: 환산 | S40: =$G39*S39 -> 0 | T40: 환산 | U40: =$G39*U39 -> 0 | W40: =$G39*W39 -> 0 | Z40: 환산 | AA40: =$G39*AA39 -> 0 | AB40: 환산 | AC40: =$G39*AC39 -> 0 | AD40: 환산 | AE40: =$G39*AE39 -> 0 | AF40: 환산 | AG40: =$G39*AG39 -> 0 | AL40: 수금 | AM40: 19500000 | AN40: 외주처리 | AO40: =SUM(AP40:BL40) -> 66000000 | AP40: 수자원 | AQ40: 66000000 | AR40: 경관 | AT40: 내역 | AV40: 용지 | AX40: 기타
...

Sheet Sheet1
E12: 55
E13: 93.5

Sheet Sheet2

Sheet Sheet3

Sheet Sheet4
